[2023-09-12 00:58:00,397][_logging.py:64 -                error() ] error from callback <function _WebSocketManager._connect.<locals>.<lambda> at 0x000001CD62C605E0>: connection to server at "localhost" (::1), port 5432 failed: FATAL:  sorry, too many clients already

[2023-09-12 00:58:00,403][_logging.py:64 -                error() ] error from callback <function _WebSocketManager._connect.<locals>.<lambda> at 0x000001CD62C68700>: connection to server at "localhost" (::1), port 5432 failed: FATAL:  sorry, too many clients already

[2023-09-12 00:58:00,431][_logging.py:64 -                error() ] error from callback <function _WebSocketManager._connect.<locals>.<lambda> at 0x000001CD609CECA0>: connection to server at "localhost" (::1), port 5432 failed: FATAL:  sorry, too many clients already

[2023-09-12 00:58:00,446][_logging.py:64 -                error() ] error from callback <function _WebSocketManager._connect.<locals>.<lambda> at 0x000001CD62D0A790>: connection to server at "localhost" (::1), port 5432 failed: FATAL:  sorry, too many clients already

[2023-09-12 00:58:00,461][_logging.py:64 -                error() ] error from callback <function _WebSocketManager._connect.<locals>.<lambda> at 0x000001CD5F727CA0>: connection to server at "localhost" (::1), port 5432 failed: FATAL:  sorry, too many clients already

[2023-09-12 00:58:00,476][_logging.py:64 -                error() ] error from callback <function _WebSocketManager._connect.<locals>.<lambda> at 0x000001CD62CE5310>: connection to server at "localhost" (::1), port 5432 failed: FATAL:  sorry, too many clients already

[2023-09-12 00:58:00,480][_logging.py:64 -                error() ] error from callback <function _WebSocketManager._connect.<locals>.<lambda> at 0x000001CD62CD2D30>: connection to server at "localhost" (::1), port 5432 failed: FATAL:  sorry, too many clients already

[2023-09-12 00:58:00,507][_logging.py:64 -                error() ] error from callback <function _WebSocketManager._connect.<locals>.<lambda> at 0x000001CD609C41F0>: connection to server at "localhost" (::1), port 5432 failed: FATAL:  sorry, too many clients already

[2023-09-12 00:58:00,523][_logging.py:64 -                error() ] error from callback <function _WebSocketManager._connect.<locals>.<lambda> at 0x000001CD5F8BA940>: connection to server at "localhost" (::1), port 5432 failed: FATAL:  sorry, too many clients already

[2023-09-12 00:58:00,527][_logging.py:64 -                error() ] error from callback <function _WebSocketManager._connect.<locals>.<lambda> at 0x000001CD62D6A3A0>: connection to server at "localhost" (::1), port 5432 failed: FATAL:  sorry, too many clients already

[2023-09-12 00:58:00,532][_logging.py:64 -                error() ] error from callback <function _WebSocketManager._connect.<locals>.<lambda> at 0x000001CD5F6ED160>: connection to server at "localhost" (::1), port 5432 failed: FATAL:  sorry, too many clients already

[2023-09-12 00:58:00,535][_logging.py:64 -                error() ] error from callback <function _WebSocketManager._connect.<locals>.<lambda> at 0x000001CD60FAC430>: connection to server at "localhost" (::1), port 5432 failed: FATAL:  sorry, too many clients already

[2023-09-12 00:58:00,539][_logging.py:64 -                error() ] error from callback <function _WebSocketManager._connect.<locals>.<lambda> at 0x000001CD626F38B0>: connection to server at "localhost" (::1), port 5432 failed: FATAL:  sorry, too many clients already

[2023-09-12 00:58:00,543][_logging.py:64 -                error() ] error from callback <function _WebSocketManager._connect.<locals>.<lambda> at 0x000001CD62D70A60>: connection to server at "localhost" (::1), port 5432 failed: FATAL:  sorry, too many clients already

[2023-09-12 00:58:00,547][_logging.py:64 -                error() ] error from callback <function _WebSocketManager._connect.<locals>.<lambda> at 0x000001CD62D70160>: connection to server at "localhost" (::1), port 5432 failed: FATAL:  sorry, too many clients already

[2023-09-12 00:58:00,551][_logging.py:64 -                error() ] error from callback <function _WebSocketManager._connect.<locals>.<lambda> at 0x000001CD5F8BDA60>: connection to server at "localhost" (::1), port 5432 failed: FATAL:  sorry, too many clients already

[2023-09-12 00:58:00,570][_logging.py:64 -                error() ] error from callback <function _WebSocketManager._connect.<locals>.<lambda> at 0x000001CD62CD2700>: connection to server at "localhost" (::1), port 5432 failed: FATAL:  sorry, too many clients already

[2023-09-12 00:58:00,585][_logging.py:64 -                error() ] error from callback <function _WebSocketManager._connect.<locals>.<lambda> at 0x000001CD62D5A3A0>: connection to server at "localhost" (::1), port 5432 failed: FATAL:  sorry, too many clients already

[2023-09-12 00:58:00,587][_logging.py:64 -                error() ] error from callback <function _WebSocketManager._connect.<locals>.<lambda> at 0x000001CD62C60820>: connection to server at "localhost" (::1), port 5432 failed: FATAL:  sorry, too many clients already

[2023-09-12 00:58:00,591][_logging.py:64 -                error() ] error from callback <function _WebSocketManager._connect.<locals>.<lambda> at 0x000001CD62C55430>: connection to server at "localhost" (::1), port 5432 failed: FATAL:  sorry, too many clients already

[2023-09-12 00:58:00,594][_logging.py:64 -                error() ] error from callback <function _WebSocketManager._connect.<locals>.<lambda> at 0x000001CD62C68940>: connection to server at "localhost" (::1), port 5432 failed: FATAL:  sorry, too many clients already

[2023-09-12 00:58:00,623][_logging.py:64 -                error() ] error from callback <function _WebSocketManager._connect.<locals>.<lambda> at 0x000001CD609CEAF0>: connection to server at "localhost" (::1), port 5432 failed: FATAL:  sorry, too many clients already

[2023-09-12 00:58:00,629][_logging.py:64 -                error() ] error from callback <function _WebSocketManager._connect.<locals>.<lambda> at 0x000001CD5F882040>: connection to server at "localhost" (::1), port 5432 failed: FATAL:  sorry, too many clients already

[2023-09-12 00:58:00,635][_logging.py:64 -                error() ] error from callback <function _WebSocketManager._connect.<locals>.<lambda> at 0x000001CD5F6DB790>: connection to server at "localhost" (::1), port 5432 failed: FATAL:  sorry, too many clients already

[2023-09-12 00:58:00,637][_logging.py:64 -                error() ] error from callback <function _WebSocketManager._connect.<locals>.<lambda> at 0x000001CD62D0A8B0>: connection to server at "localhost" (::1), port 5432 failed: FATAL:  sorry, too many clients already

[2023-09-12 00:58:00,639][_logging.py:64 -                error() ] error from callback <function _WebSocketManager._connect.<locals>.<lambda> at 0x000001CD62D66A60>: connection to server at "localhost" (::1), port 5432 failed: FATAL:  sorry, too many clients already

[2023-09-12 00:58:00,653][_logging.py:64 -                error() ] error from callback <function _WebSocketManager._connect.<locals>.<lambda> at 0x000001CD5F727DC0>: connection to server at "localhost" (::1), port 5432 failed: FATAL:  sorry, too many clients already

[2023-09-12 00:58:00,670][_logging.py:64 -                error() ] error from callback <function _WebSocketManager._connect.<locals>.<lambda> at 0x000001CD62CE5430>: connection to server at "localhost" (::1), port 5432 failed: FATAL:  sorry, too many clients already

[2023-09-12 00:58:00,675][_logging.py:64 -                error() ] error from callback <function _WebSocketManager._connect.<locals>.<lambda> at 0x000001CD62CD2EE0>: connection to server at "localhost" (::1), port 5432 failed: FATAL:  sorry, too many clients already

[2023-09-12 00:58:00,701][_logging.py:64 -                error() ] error from callback <function _WebSocketManager._connect.<locals>.<lambda> at 0x000001CD609C4550>: connection to server at "localhost" (::1), port 5432 failed: FATAL:  sorry, too many clients already

[2023-09-12 00:58:00,717][_logging.py:64 -                error() ] error from callback <function _WebSocketManager._connect.<locals>.<lambda> at 0x000001CD5F8BAB80>: connection to server at "localhost" (::1), port 5432 failed: FATAL:  sorry, too many clients already

[2023-09-12 00:58:00,718][_logging.py:64 -                error() ] error from callback <function _WebSocketManager._connect.<locals>.<lambda> at 0x000001CD62D6A8B0>: connection to server at "localhost" (::1), port 5432 failed: FATAL:  sorry, too many clients already

[2023-09-12 00:58:00,724][_logging.py:64 -                error() ] error from callback <function _WebSocketManager._connect.<locals>.<lambda> at 0x000001CD60FAC9D0>: connection to server at "localhost" (::1), port 5432 failed: FATAL:  sorry, too many clients already

[2023-09-12 00:58:00,725][_logging.py:64 -                error() ] error from callback <function _WebSocketManager._connect.<locals>.<lambda> at 0x000001CD5F6ED310>: connection to server at "localhost" (::1), port 5432 failed: FATAL:  sorry, too many clients already

[2023-09-12 00:58:00,730][_logging.py:64 -                error() ] error from callback <function _WebSocketManager._connect.<locals>.<lambda> at 0x000001CD626F39D0>: connection to server at "localhost" (::1), port 5432 failed: FATAL:  sorry, too many clients already

[2023-09-12 00:58:00,733][_logging.py:64 -                error() ] error from callback <function _WebSocketManager._connect.<locals>.<lambda> at 0x000001CD62D70B80>: connection to server at "localhost" (::1), port 5432 failed: FATAL:  sorry, too many clients already

[2023-09-12 00:58:00,742][_logging.py:64 -                error() ] error from callback <function _WebSocketManager._connect.<locals>.<lambda> at 0x000001CD62D70700>: connection to server at "localhost" (::1), port 5432 failed: FATAL:  sorry, too many clients already

[2023-09-12 00:58:00,743][_logging.py:64 -                error() ] error from callback <function _WebSocketManager._connect.<locals>.<lambda> at 0x000001CD5F8BDCA0>: connection to server at "localhost" (::1), port 5432 failed: FATAL:  sorry, too many clients already

[2023-09-12 00:58:00,767][_logging.py:64 -                error() ] error from callback <function _WebSocketManager._connect.<locals>.<lambda> at 0x000001CD62CD2790>: connection to server at "localhost" (::1), port 5432 failed: FATAL:  sorry, too many clients already

[2023-09-12 00:58:00,776][_logging.py:64 -                error() ] error from callback <function _WebSocketManager._connect.<locals>.<lambda> at 0x000001CD62D5A5E0>: connection to server at "localhost" (::1), port 5432 failed: FATAL:  sorry, too many clients already

[2023-09-12 00:58:00,781][_logging.py:64 -                error() ] error from callback <function _WebSocketManager._connect.<locals>.<lambda> at 0x000001CD62C554C0>: connection to server at "localhost" (::1), port 5432 failed: FATAL:  sorry, too many clients already

[2023-09-12 00:58:00,821][_logging.py:64 -                error() ] error from callback <function _WebSocketManager._connect.<locals>.<lambda> at 0x000001CD5F8821F0>: connection to server at "localhost" (::1), port 5432 failed: FATAL:  sorry, too many clients already

[2023-09-12 00:58:00,831][_logging.py:64 -                error() ] error from callback <function _WebSocketManager._connect.<locals>.<lambda> at 0x000001CD5F6DB820>: connection to server at "localhost" (::1), port 5432 failed: FATAL:  sorry, too many clients already

[2023-09-12 00:58:00,831][_logging.py:64 -                error() ] error from callback <function _WebSocketManager._connect.<locals>.<lambda> at 0x000001CD62D6A160>: connection to server at "localhost" (::1), port 5432 failed: FATAL:  sorry, too many clients already

[2023-09-12 01:13:25,744][market.py:97 -     update_coin_info() ] create_csv() missing 1 required positional argument: 'limit'
Traceback (most recent call last):
  File "C:\Users\fatih\PycharmProjects\TAtest\tradebot\market.py", line 93, in update_coin_info
    create_csv(ids_path=ids_path, data_path=path)
TypeError: create_csv() missing 1 required positional argument: 'limit'
[2023-09-12 21:40:15,373][db.py:132 -      insert_from_csv() ] extra data after last expected column
CONTEXT:  COPY CoinInfo, line 1: "1,Bitcoin,BTC,19483556,18818282930.45413,506115394463.771,3.72"
Traceback (most recent call last):
  File "C:\Users\fatih\PycharmProjects\TAtest\tradebot\db.py", line 127, in insert_from_csv
    cur.copy_from(file=file, table=tablename, sep=',')
psycopg2.errors.BadCopyFileFormat: extra data after last expected column
CONTEXT:  COPY CoinInfo, line 1: "1,Bitcoin,BTC,19483556,18818282930.45413,506115394463.771,3.72"

[2023-09-12 21:40:15,374][market.py:96 -     update_coin_info() ] extra data after last expected column
CONTEXT:  COPY CoinInfo, line 1: "1,Bitcoin,BTC,19483556,18818282930.45413,506115394463.771,3.72"
Traceback (most recent call last):
  File "C:\Users\fatih\PycharmProjects\TAtest\tradebot\market.py", line 94, in update_coin_info
    self.db.insert_from_csv(tablename='CoinInfo', csv_path=config.CMC_DATA_PATH)
  File "C:\Users\fatih\PycharmProjects\TAtest\tradebot\db.py", line 133, in insert_from_csv
    raise e
  File "C:\Users\fatih\PycharmProjects\TAtest\tradebot\db.py", line 127, in insert_from_csv
    cur.copy_from(file=file, table=tablename, sep=',')
psycopg2.errors.BadCopyFileFormat: extra data after last expected column
CONTEXT:  COPY CoinInfo, line 1: "1,Bitcoin,BTC,19483556,18818282930.45413,506115394463.771,3.72"

[2023-09-17 21:50:24,864][db.py:47 -              connect() ] connection to server at "localhost" (::1), port 5432 failed: Connection refused (0x0000274D/10061)
	Is the server running on that host and accepting TCP/IP connections?
connection to server at "localhost" (127.0.0.1), port 5432 failed: Connection refused (0x0000274D/10061)
	Is the server running on that host and accepting TCP/IP connections?
Traceback (most recent call last):
  File "C:\Users\fatih\PycharmProjects\TAtest\tradebot\db.py", line 37, in connect
    self.conn = pool.ThreadedConnectionPool(
  File "C:\Users\fatih\PycharmProjects\LolCharacterRecognition39\TAtest\lib\site-packages\psycopg2\pool.py", line 161, in __init__
    AbstractConnectionPool.__init__(
  File "C:\Users\fatih\PycharmProjects\LolCharacterRecognition39\TAtest\lib\site-packages\psycopg2\pool.py", line 59, in __init__
    self._connect()
  File "C:\Users\fatih\PycharmProjects\LolCharacterRecognition39\TAtest\lib\site-packages\psycopg2\pool.py", line 63, in _connect
    conn = psycopg2.connect(*self._args, **self._kwargs)
  File "C:\Users\fatih\PycharmProjects\LolCharacterRecognition39\TAtest\lib\site-packages\psycopg2\__init__.py", line 122, in connect
    conn = _connect(dsn, connection_factory=connection_factory, **kwasync)
psycopg2.OperationalError: connection to server at "localhost" (::1), port 5432 failed: Connection refused (0x0000274D/10061)
	Is the server running on that host and accepting TCP/IP connections?
connection to server at "localhost" (127.0.0.1), port 5432 failed: Connection refused (0x0000274D/10061)
	Is the server running on that host and accepting TCP/IP connections?

[2023-09-18 20:54:39,225][db.py:47 -              connect() ] connection to server on socket "/var/run/postgresql/.s.PGSQL.5432" failed: FATAL:  role "fatih" does not exist
Traceback (most recent call last):
  File "/home/fatih/bot/tradebot/db.py", line 37, in connect
    self.conn = pool.ThreadedConnectionPool(
  File "/home/fatih/bot/my_venv/lib/python3.10/site-packages/psycopg2/pool.py", line 161, in __init__
    AbstractConnectionPool.__init__(
  File "/home/fatih/bot/my_venv/lib/python3.10/site-packages/psycopg2/pool.py", line 59, in __init__
    self._connect()
  File "/home/fatih/bot/my_venv/lib/python3.10/site-packages/psycopg2/pool.py", line 63, in _connect
    conn = psycopg2.connect(*self._args, **self._kwargs)
  File "/home/fatih/bot/my_venv/lib/python3.10/site-packages/psycopg2/__init__.py", line 122, in connect
    conn = _connect(dsn, connection_factory=connection_factory, **kwasync)
psycopg2.OperationalError: connection to server on socket "/var/run/postgresql/.s.PGSQL.5432" failed: FATAL:  role "fatih" does not exist

[2023-09-18 20:55:41,109][db.py:47 -              connect() ] connection to server at "localhost" (127.0.0.1), port 5432 failed: FATAL:  database "testdb" does not exist
Traceback (most recent call last):
  File "/home/fatih/bot/tradebot/db.py", line 37, in connect
    self.conn = pool.ThreadedConnectionPool(
  File "/home/fatih/bot/my_venv/lib/python3.10/site-packages/psycopg2/pool.py", line 161, in __init__
    AbstractConnectionPool.__init__(
  File "/home/fatih/bot/my_venv/lib/python3.10/site-packages/psycopg2/pool.py", line 59, in __init__
    self._connect()
  File "/home/fatih/bot/my_venv/lib/python3.10/site-packages/psycopg2/pool.py", line 63, in _connect
    conn = psycopg2.connect(*self._args, **self._kwargs)
  File "/home/fatih/bot/my_venv/lib/python3.10/site-packages/psycopg2/__init__.py", line 122, in connect
    conn = _connect(dsn, connection_factory=connection_factory, **kwasync)
psycopg2.OperationalError: connection to server at "localhost" (127.0.0.1), port 5432 failed: FATAL:  database "testdb" does not exist

[2023-09-18 23:19:41,418][_logging.py:64 -                error() ] error from callback <function _WebSocketManager._connect.<locals>.<lambda> at 0x7ff0425f0820>: Invalid input of type: 'tuple'. Convert to a bytes, string, int or float first.
[2023-09-18 23:19:41,610][_logging.py:64 -                error() ] error from callback <function _WebSocketManager._connect.<locals>.<lambda> at 0x7ff0425f09d0>: Invalid input of type: 'tuple'. Convert to a bytes, string, int or float first.
[2023-09-18 23:33:01,842][_logging.py:64 -                error() ] error from callback <function _WebSocketManager._connect.<locals>.<lambda> at 0x7fe9f19e8940>: 'NoneType' object has no attribute 'publish'
[2023-09-18 23:33:02,031][_logging.py:64 -                error() ] error from callback <function _WebSocketManager._connect.<locals>.<lambda> at 0x7fe9f19e8af0>: 'NoneType' object has no attribute 'publish'
[2023-09-21 23:03:08,442][_logging.py:64 -                error() ] error from callback <function _WebSocketManager._connect.<locals>.<lambda> at 0x7fd73675f370>: Authorization for Unified V5 (Auth) failed. Please check your API keys and restart. Raw error: {'success': False, 'ret_msg': 'Params Error', 'op': 'auth', 'conn_id': 'ck4hh5hqo29qn0moor60-wxh'}
[2023-09-21 23:03:08,677][_logging.py:64 -                error() ] error from callback <function _WebSocketManager._connect.<locals>.<lambda> at 0x7fd722dea9e0>: Authorization for Unified V5 (Auth) failed. Please check your API keys and restart. Raw error: {'success': False, 'ret_msg': 'Params Error', 'op': 'auth', 'conn_id': 'ck4hh5hqo29qn0moor60-wxh'}
[2023-09-21 23:06:15,465][_logging.py:64 -                error() ] error from callback <function _WebSocketManager._connect.<locals>.<lambda> at 0x7f495e707370>: Authorization for Unified V5 (Auth) failed. Please check your API keys and restart. Raw error: {'success': False, 'ret_msg': 'Params Error', 'op': 'auth', 'conn_id': 'ck4hhhddaugqefbq5isg-wug'}
[2023-09-21 23:06:15,660][_logging.py:64 -                error() ] error from callback <function _WebSocketManager._connect.<locals>.<lambda> at 0x7f494adeea70>: Authorization for Unified V5 (Auth) failed. Please check your API keys and restart. Raw error: {'success': False, 'ret_msg': 'Params Error', 'op': 'auth', 'conn_id': 'ck4hhhddaugqefbq5isg-wug'}
[2023-09-21 23:16:57,867][_http_manager.py:335 -      _submit_request() ] invalid request, please check your server timestamp or recv_window param. req_timestamp[1695327427666],server_timestamp[1695327419365],recv_window[5000] (ErrCode: 10002). Added 2.5 seconds to recv_window. 2 retries remain.
[2023-09-21 23:17:01,410][_http_manager.py:335 -      _submit_request() ] invalid request, please check your server timestamp or recv_window param. req_timestamp[1695327430870],server_timestamp[1695327422908],recv_window[7500] (ErrCode: 10002). Added 2.5 seconds to recv_window. 1 retries remain.
[2023-09-21 23:17:04,970][_http_manager.py:335 -      _submit_request() ] invalid request, please check your server timestamp or recv_window param. req_timestamp[1695327434413],server_timestamp[1695327426457],recv_window[10000] (ErrCode: 10002). Added 2.5 seconds to recv_window. 0 retries remain.
[2023-09-21 23:30:16,749][_http_manager.py:335 -      _submit_request() ] invalid request, please check your server timestamp or recv_window param. req_timestamp[1695328226211],server_timestamp[1695328216653],recv_window[5000] (ErrCode: 10002). Added 2.5 seconds to recv_window. 2 retries remain.
[2023-09-21 23:30:20,297][_http_manager.py:335 -      _submit_request() ] invalid request, please check your server timestamp or recv_window param. req_timestamp[1695328229751],server_timestamp[1695328220202],recv_window[7500] (ErrCode: 10002). Added 2.5 seconds to recv_window. 1 retries remain.
[2023-09-21 23:30:23,501][_http_manager.py:335 -      _submit_request() ] invalid request, please check your server timestamp or recv_window param. req_timestamp[1695328233300],server_timestamp[1695328223406],recv_window[10000] (ErrCode: 10002). Added 2.5 seconds to recv_window. 0 retries remain.
[2023-09-21 23:34:03,002][_http_manager.py:335 -      _submit_request() ] invalid request, please check your server timestamp or recv_window param. req_timestamp[1695328542464],server_timestamp[1695328444552],recv_window[5000] (ErrCode: 10002). Added 2.5 seconds to recv_window. 2 retries remain.
[2023-09-21 23:34:06,548][_http_manager.py:335 -      _submit_request() ] invalid request, please check your server timestamp or recv_window param. req_timestamp[1695328546006],server_timestamp[1695328448095],recv_window[7500] (ErrCode: 10002). Added 2.5 seconds to recv_window. 1 retries remain.
[2023-09-21 23:39:36,611][_http_manager.py:335 -      _submit_request() ] invalid request, please check your server timestamp or recv_window param. req_timestamp[1695328786080],server_timestamp[1695328776517],recv_window[5000] (ErrCode: 10002). Added 2.5 seconds to recv_window. 2 retries remain.
[2023-09-21 23:39:40,159][_http_manager.py:335 -      _submit_request() ] invalid request, please check your server timestamp or recv_window param. req_timestamp[1695328789614],server_timestamp[1695328780063],recv_window[7500] (ErrCode: 10002). Added 2.5 seconds to recv_window. 1 retries remain.
[2023-09-21 23:40:27,901][_http_manager.py:335 -      _submit_request() ] invalid request, please check your server timestamp or recv_window param. req_timestamp[1695328837359],server_timestamp[1695328827807],recv_window[5000] (ErrCode: 10002). Added 2.5 seconds to recv_window. 2 retries remain.
[2023-09-21 23:40:31,452][_http_manager.py:335 -      _submit_request() ] invalid request, please check your server timestamp or recv_window param. req_timestamp[1695328840904],server_timestamp[1695328831358],recv_window[7500] (ErrCode: 10002). Added 2.5 seconds to recv_window. 1 retries remain.
[2023-09-21 23:40:34,983][_http_manager.py:335 -      _submit_request() ] invalid request, please check your server timestamp or recv_window param. req_timestamp[1695328844455],server_timestamp[1695328834892],recv_window[10000] (ErrCode: 10002). Added 2.5 seconds to recv_window. 0 retries remain.
[2023-09-22 13:35:19,200][_http_manager.py:335 -      _submit_request() ] invalid request, please check your server timestamp or recv_window param. req_timestamp[1695378929004],server_timestamp[1695378919526],recv_window[5000] (ErrCode: 10002). Added 2.5 seconds to recv_window. 2 retries remain.
[2023-09-22 13:35:22,741][_http_manager.py:335 -      _submit_request() ] invalid request, please check your server timestamp or recv_window param. req_timestamp[1695378932204],server_timestamp[1695378923064],recv_window[7500] (ErrCode: 10002). Added 2.5 seconds to recv_window. 1 retries remain.
[2023-09-22 13:35:26,279][_http_manager.py:335 -      _submit_request() ] invalid request, please check your server timestamp or recv_window param. req_timestamp[1695378935744],server_timestamp[1695378926604],recv_window[10000] (ErrCode: 10002). Added 2.5 seconds to recv_window. 0 retries remain.
[2023-09-22 13:50:27,913][_logging.py:64 -                error() ] error from callback <function _WebSocketManager._connect.<locals>.<lambda> at 0x7f361b897370>: Invalid input of type: 'dict'. Convert to a bytes, string, int or float first.
[2023-09-22 13:50:28,109][_logging.py:64 -                error() ] error from callback <function _WebSocketManager._connect.<locals>.<lambda> at 0x7f36081d69e0>: Invalid input of type: 'dict'. Convert to a bytes, string, int or float first.
[2023-09-22 18:57:24,632][_logging.py:64 -                error() ] error from callback <function _WebSocketManager._connect.<locals>.<lambda> at 0x7fb437dea710>: Authorization for Unified V5 (Auth) failed. Please check your API keys and restart. Raw error: {'success': False, 'ret_msg': 'Params Error', 'op': 'auth', 'conn_id': 'ck4hhhddaugqefbq5isg-17e2'}
[2023-09-22 18:57:24,854][_logging.py:64 -                error() ] error from callback <function _WebSocketManager._connect.<locals>.<lambda> at 0x7fb437dea830>: Authorization for Unified V5 (Auth) failed. Please check your API keys and restart. Raw error: {'success': False, 'ret_msg': 'Params Error', 'op': 'auth', 'conn_id': 'ck4hhhddaugqefbq5isg-17e2'}
[2023-09-22 18:57:57,077][_logging.py:64 -                error() ] error from callback <function _WebSocketManager._connect.<locals>.<lambda> at 0x7fd4b4fee830>: Authorization for Unified V5 (Auth) failed. Please check your API keys and restart. Raw error: {'success': False, 'ret_msg': 'Params Error', 'op': 'auth', 'conn_id': 'ck4hhhddaugqefbq5isg-17ea'}
[2023-09-22 18:57:57,297][_logging.py:64 -                error() ] error from callback <function _WebSocketManager._connect.<locals>.<lambda> at 0x7fd4b4fee950>: Authorization for Unified V5 (Auth) failed. Please check your API keys and restart. Raw error: {'success': False, 'ret_msg': 'Params Error', 'op': 'auth', 'conn_id': 'ck4hhhddaugqefbq5isg-17ea'}
[2023-09-22 19:00:54,321][_logging.py:64 -                error() ] error from callback <function _WebSocketManager._connect.<locals>.<lambda> at 0x7fa8d51f2830>: Authorization for Unified V5 (Auth) failed. Please check your API keys and restart. Raw error: {'success': False, 'ret_msg': 'Params Error', 'op': 'auth', 'conn_id': 'ck4hh5hqo29qn0moor60-17jm'}
[2023-09-22 19:00:54,537][_logging.py:64 -                error() ] error from callback <function _WebSocketManager._connect.<locals>.<lambda> at 0x7fa8d51f2950>: Authorization for Unified V5 (Auth) failed. Please check your API keys and restart. Raw error: {'success': False, 'ret_msg': 'Params Error', 'op': 'auth', 'conn_id': 'ck4hh5hqo29qn0moor60-17jm'}
[2023-09-22 19:04:01,368][_logging.py:64 -                error() ] error from callback <function _WebSocketManager._connect.<locals>.<lambda> at 0x7f9d679de8c0>: Authorization for Unified V5 (Auth) failed. Please check your API keys and restart. Raw error: {'success': False, 'ret_msg': 'Params Error', 'op': 'auth', 'conn_id': 'ck4hhhddaugqefbq5isg-17h5'}
[2023-09-22 19:04:01,584][_logging.py:64 -                error() ] error from callback <function _WebSocketManager._connect.<locals>.<lambda> at 0x7f9d679de9e0>: Authorization for Unified V5 (Auth) failed. Please check your API keys and restart. Raw error: {'success': False, 'ret_msg': 'Params Error', 'op': 'auth', 'conn_id': 'ck4hhhddaugqefbq5isg-17h5'}
[2023-09-22 19:07:09,813][_logging.py:64 -                error() ] error from callback <function _WebSocketManager._connect.<locals>.<lambda> at 0x7f00079da830>: Authorization for Unified V5 (Auth) failed. Please check your API keys and restart. Raw error: {'success': False, 'ret_msg': 'Params Error', 'op': 'auth', 'conn_id': 'ck4hhhddaugqefbq5isg-17il'}
[2023-09-22 19:07:10,032][_logging.py:64 -                error() ] error from callback <function _WebSocketManager._connect.<locals>.<lambda> at 0x7f00079da950>: Authorization for Unified V5 (Auth) failed. Please check your API keys and restart. Raw error: {'success': False, 'ret_msg': 'Params Error', 'op': 'auth', 'conn_id': 'ck4hhhddaugqefbq5isg-17il'}
[2023-09-22 19:17:17,582][_logging.py:64 -                error() ] error from callback <function _WebSocketManager._connect.<locals>.<lambda> at 0x7f1f353d28c0>: Authorization for Unified V5 (Auth) failed. Please check your API keys and restart. Raw error: {'success': False, 'ret_msg': 'Params Error', 'op': 'auth', 'conn_id': 'ck4hhhddaugqefbq5isg-17p5'}
[2023-09-22 19:17:17,801][_logging.py:64 -                error() ] error from callback <function _WebSocketManager._connect.<locals>.<lambda> at 0x7f1f353d29e0>: Authorization for Unified V5 (Auth) failed. Please check your API keys and restart. Raw error: {'success': False, 'ret_msg': 'Params Error', 'op': 'auth', 'conn_id': 'ck4hhhddaugqefbq5isg-17p5'}
[2023-09-22 19:21:04,499][_logging.py:64 -                error() ] error from callback <function _WebSocketManager._connect.<locals>.<lambda> at 0x7fee0d9e6950>: Authorization for Unified V5 (Auth) failed. Please check your API keys and restart. Raw error: {'success': False, 'ret_msg': 'Params Error', 'op': 'auth', 'conn_id': 'ck4hh5hqo29qn0moor60-17vn'}
[2023-09-22 19:21:04,723][_logging.py:64 -                error() ] error from callback <function _WebSocketManager._connect.<locals>.<lambda> at 0x7fee0d9e6a70>: Authorization for Unified V5 (Auth) failed. Please check your API keys and restart. Raw error: {'success': False, 'ret_msg': 'Params Error', 'op': 'auth', 'conn_id': 'ck4hh5hqo29qn0moor60-17vn'}
[2023-09-22 20:38:05,597][_logging.py:64 -                error() ] error from callback <function _WebSocketManager._connect.<locals>.<lambda> at 0x7f480e9ee950>: Authorization for Unified V5 (Auth) failed. Please check your API keys and restart. Raw error: {'success': False, 'ret_msg': 'Params Error', 'op': 'auth', 'conn_id': 'ck4hh5hqo29qn0moor60-192q'}
[2023-09-22 20:38:05,816][_logging.py:64 -                error() ] error from callback <function _WebSocketManager._connect.<locals>.<lambda> at 0x7f480e9eea70>: Authorization for Unified V5 (Auth) failed. Please check your API keys and restart. Raw error: {'success': False, 'ret_msg': 'Params Error', 'op': 'auth', 'conn_id': 'ck4hh5hqo29qn0moor60-192q'}
[2023-09-22 20:39:00,549][_logging.py:64 -                error() ] error from callback <function _WebSocketManager._connect.<locals>.<lambda> at 0x7fb99e3ea950>: Authorization for Unified V5 (Auth) failed. Please check your API keys and restart. Raw error: {'success': False, 'ret_msg': 'Params Error', 'op': 'auth', 'conn_id': 'ck4hhhddaugqefbq5isg-18z6'}
[2023-09-22 20:39:00,786][_logging.py:64 -                error() ] error from callback <function _WebSocketManager._connect.<locals>.<lambda> at 0x7fb99e3eaa70>: Authorization for Unified V5 (Auth) failed. Please check your API keys and restart. Raw error: {'success': False, 'ret_msg': 'Params Error', 'op': 'auth', 'conn_id': 'ck4hhhddaugqefbq5isg-18z6'}
[2023-09-24 23:07:31,332][_logging.py:64 -                error() ] error from callback <function _WebSocketManager._connect.<locals>.<lambda> at 0x7fe5cc7d2950>: Authorization for Unified V5 (Auth) failed. Please check your API keys and restart. Raw error: {'success': False, 'ret_msg': 'Params Error', 'op': 'auth', 'conn_id': 'ck4hhhddaugqefbq5isg-1und'}
[2023-09-24 23:07:31,551][_logging.py:64 -                error() ] error from callback <function _WebSocketManager._connect.<locals>.<lambda> at 0x7fe5cc7d2a70>: Authorization for Unified V5 (Auth) failed. Please check your API keys and restart. Raw error: {'success': False, 'ret_msg': 'Params Error', 'op': 'auth', 'conn_id': 'ck4hhhddaugqefbq5isg-1und'}
[2023-09-24 23:12:15,584][_logging.py:64 -                error() ] error from callback <function _WebSocketManager._connect.<locals>.<lambda> at 0x7fa56f5d2b00>: Authorization for Unified V5 (Auth) failed. Please check your API keys and restart. Raw error: {'success': False, 'ret_msg': 'Params Error', 'op': 'auth', 'conn_id': 'ck4hh5hqo29qn0moor60-1us3'}
[2023-09-24 23:12:15,800][_logging.py:64 -                error() ] error from callback <function _WebSocketManager._connect.<locals>.<lambda> at 0x7fa56f5d2c20>: Authorization for Unified V5 (Auth) failed. Please check your API keys and restart. Raw error: {'success': False, 'ret_msg': 'Params Error', 'op': 'auth', 'conn_id': 'ck4hh5hqo29qn0moor60-1us3'}
[2023-09-24 23:27:42,170][_logging.py:64 -                error() ] error from callback <function _WebSocketManager._connect.<locals>.<lambda> at 0x7f11189d6b00>: Authorization for Unified V5 (Auth) failed. Please check your API keys and restart. Raw error: {'success': False, 'ret_msg': 'Params Error', 'op': 'auth', 'conn_id': 'ck4hhhddaugqefbq5isg-1us6'}
[2023-09-24 23:27:42,391][_logging.py:64 -                error() ] error from callback <function _WebSocketManager._connect.<locals>.<lambda> at 0x7f11189d6c20>: Authorization for Unified V5 (Auth) failed. Please check your API keys and restart. Raw error: {'success': False, 'ret_msg': 'Params Error', 'op': 'auth', 'conn_id': 'ck4hhhddaugqefbq5isg-1us6'}
[2023-09-24 23:36:57,243][_logging.py:64 -                error() ] error from callback <function _WebSocketManager._connect.<locals>.<lambda> at 0x7f2f365e55a0>: Error 111 connecting to localhost:6379. Connection refused.
[2023-09-24 23:36:57,488][_logging.py:64 -                error() ] error from callback <function _WebSocketManager._connect.<locals>.<lambda> at 0x7f2f365e64d0>: Error 111 connecting to localhost:6379. Connection refused.
[2023-09-25 19:38:03,871][_logging.py:64 -                error() ] error from callback <function _WebSocketManager._connect.<locals>.<lambda> at 0x7fcc71feea70>: Authorization for Unified V5 (Auth) failed. Please check your API keys and restart. Raw error: {'success': False, 'ret_msg': 'Params Error', 'op': 'auth', 'conn_id': 'ck4hh5hqo29qn0moor60-27ir'}
[2023-09-25 19:38:04,128][_logging.py:64 -                error() ] error from callback <function _WebSocketManager._connect.<locals>.<lambda> at 0x7fcc71feeb90>: Authorization for Unified V5 (Auth) failed. Please check your API keys and restart. Raw error: {'success': False, 'ret_msg': 'Params Error', 'op': 'auth', 'conn_id': 'ck4hh5hqo29qn0moor60-27ir'}
[2023-09-25 19:39:34,373][_logging.py:64 -                error() ] error from callback <function _WebSocketManager._connect.<locals>.<lambda> at 0x7f32453eab90>: Authorization for Unified V5 (Auth) failed. Please check your API keys and restart. Raw error: {'success': False, 'ret_msg': 'Params Error', 'op': 'auth', 'conn_id': 'ck4hhhddaugqefbq5isg-27fs'}
[2023-09-25 19:39:34,592][_logging.py:64 -                error() ] error from callback <function _WebSocketManager._connect.<locals>.<lambda> at 0x7f32453eacb0>: Authorization for Unified V5 (Auth) failed. Please check your API keys and restart. Raw error: {'success': False, 'ret_msg': 'Params Error', 'op': 'auth', 'conn_id': 'ck4hhhddaugqefbq5isg-27fs'}
[2023-09-25 19:54:58,311][_logging.py:64 -                error() ] error from callback <function _WebSocketManager._connect.<locals>.<lambda> at 0x7f9a6b1ea9e0>: Authorization for Unified V5 (Auth) failed. Please check your API keys and restart. Raw error: {'success': False, 'ret_msg': 'Params Error', 'op': 'auth', 'conn_id': 'ck4hh5hqo29qn0moor60-27pf'}
[2023-09-25 19:54:58,529][_logging.py:64 -                error() ] error from callback <function _WebSocketManager._connect.<locals>.<lambda> at 0x7f9a6b1eab00>: Authorization for Unified V5 (Auth) failed. Please check your API keys and restart. Raw error: {'success': False, 'ret_msg': 'Params Error', 'op': 'auth', 'conn_id': 'ck4hh5hqo29qn0moor60-27pf'}
[2023-09-25 20:04:39,163][_logging.py:64 -                error() ] error from callback <function _WebSocketManager._connect.<locals>.<lambda> at 0x7fdde6dea9e0>: Authorization for Unified V5 (Auth) failed. Please check your API keys and restart. Raw error: {'success': False, 'ret_msg': 'Params Error', 'op': 'auth', 'conn_id': 'ck4hh5hqo29qn0moor60-27ta'}
[2023-09-25 20:04:39,386][_logging.py:64 -                error() ] error from callback <function _WebSocketManager._connect.<locals>.<lambda> at 0x7fdde6deab00>: Authorization for Unified V5 (Auth) failed. Please check your API keys and restart. Raw error: {'success': False, 'ret_msg': 'Params Error', 'op': 'auth', 'conn_id': 'ck4hh5hqo29qn0moor60-27ta'}
[2023-09-25 20:25:11,986][_logging.py:64 -                error() ] error from callback <function _WebSocketManager._connect.<locals>.<lambda> at 0x7f699f1eea70>: Authorization for Unified V5 (Auth) failed. Please check your API keys and restart. Raw error: {'success': False, 'ret_msg': 'Params Error', 'op': 'auth', 'conn_id': 'ck4hhhddaugqefbq5isg-27xb'}
[2023-09-25 20:25:12,207][_logging.py:64 -                error() ] error from callback <function _WebSocketManager._connect.<locals>.<lambda> at 0x7f699f1eeb90>: Authorization for Unified V5 (Auth) failed. Please check your API keys and restart. Raw error: {'success': False, 'ret_msg': 'Params Error', 'op': 'auth', 'conn_id': 'ck4hhhddaugqefbq5isg-27xb'}
[2023-09-25 20:32:03,472][_logging.py:64 -                error() ] error from callback <function _WebSocketManager._connect.<locals>.<lambda> at 0x7f18a9dd2a70>: Authorization for Unified V5 (Auth) failed. Please check your API keys and restart. Raw error: {'success': False, 'ret_msg': 'Params Error', 'op': 'auth', 'conn_id': 'ck4hh5hqo29qn0moor60-283q'}
[2023-09-25 20:32:03,677][_logging.py:64 -                error() ] error from callback <function _WebSocketManager._connect.<locals>.<lambda> at 0x7f18a9dd2b90>: Authorization for Unified V5 (Auth) failed. Please check your API keys and restart. Raw error: {'success': False, 'ret_msg': 'Params Error', 'op': 'auth', 'conn_id': 'ck4hh5hqo29qn0moor60-283q'}
[2023-09-25 20:32:38,956][_logging.py:64 -                error() ] error from callback <function _WebSocketManager._connect.<locals>.<lambda> at 0x7efe0cbd2a70>: Authorization for Unified V5 (Auth) failed. Please check your API keys and restart. Raw error: {'success': False, 'ret_msg': 'Params Error', 'op': 'auth', 'conn_id': 'ck4hh5hqo29qn0moor60-2842'}
[2023-09-25 20:32:39,158][_logging.py:64 -                error() ] error from callback <function _WebSocketManager._connect.<locals>.<lambda> at 0x7efe0cbd2b90>: Authorization for Unified V5 (Auth) failed. Please check your API keys and restart. Raw error: {'success': False, 'ret_msg': 'Params Error', 'op': 'auth', 'conn_id': 'ck4hh5hqo29qn0moor60-2842'}
[2023-09-25 22:32:11,234][_logging.py:64 -                error() ] error from callback <function _WebSocketManager._connect.<locals>.<lambda> at 0x7f2a783d2a70>: Authorization for Unified V5 (Auth) failed. Please check your API keys and restart. Raw error: {'success': False, 'ret_msg': 'Params Error', 'op': 'auth', 'conn_id': 'ck4hh5hqo29qn0moor60-29hp'}
[2023-09-25 22:32:11,469][_logging.py:64 -                error() ] error from callback <function _WebSocketManager._connect.<locals>.<lambda> at 0x7f2a783d2b90>: Authorization for Unified V5 (Auth) failed. Please check your API keys and restart. Raw error: {'success': False, 'ret_msg': 'Params Error', 'op': 'auth', 'conn_id': 'ck4hh5hqo29qn0moor60-29hp'}
[2023-09-25 22:45:42,413][_logging.py:64 -                error() ] error from callback <function _WebSocketManager._connect.<locals>.<lambda> at 0x7eff2c9f29e0>: Authorization for Unified V5 (Auth) failed. Please check your API keys and restart. Raw error: {'success': False, 'ret_msg': 'Params Error', 'op': 'auth', 'conn_id': 'ck4hh5hqo29qn0moor60-29n3'}
[2023-09-25 22:45:42,629][_logging.py:64 -                error() ] error from callback <function _WebSocketManager._connect.<locals>.<lambda> at 0x7eff2c9f2b00>: Authorization for Unified V5 (Auth) failed. Please check your API keys and restart. Raw error: {'success': False, 'ret_msg': 'Params Error', 'op': 'auth', 'conn_id': 'ck4hh5hqo29qn0moor60-29n3'}
[2023-09-25 22:45:56,941][_logging.py:64 -                error() ] error from callback <function _WebSocketManager._connect.<locals>.<lambda> at 0x7f0d701f2a70>: Authorization for Unified V5 (Auth) failed. Please check your API keys and restart. Raw error: {'success': False, 'ret_msg': 'Params Error', 'op': 'auth', 'conn_id': 'ck4hhhddaugqefbq5isg-29jj'}
[2023-09-25 22:45:57,158][_logging.py:64 -                error() ] error from callback <function _WebSocketManager._connect.<locals>.<lambda> at 0x7f0d701f2b90>: Authorization for Unified V5 (Auth) failed. Please check your API keys and restart. Raw error: {'success': False, 'ret_msg': 'Params Error', 'op': 'auth', 'conn_id': 'ck4hhhddaugqefbq5isg-29jj'}
[2023-09-25 23:23:35,403][_logging.py:64 -                error() ] error from callback <function _WebSocketManager._connect.<locals>.<lambda> at 0x7fabddfeea70>: Authorization for Unified V5 (Auth) failed. Please check your API keys and restart. Raw error: {'success': False, 'ret_msg': 'Params Error', 'op': 'auth', 'conn_id': 'ck4hhhddaugqefbq5isg-2a15'}
[2023-09-25 23:23:35,631][_logging.py:64 -                error() ] error from callback <function _WebSocketManager._connect.<locals>.<lambda> at 0x7fabddfeeb90>: Authorization for Unified V5 (Auth) failed. Please check your API keys and restart. Raw error: {'success': False, 'ret_msg': 'Params Error', 'op': 'auth', 'conn_id': 'ck4hhhddaugqefbq5isg-2a15'}
[2023-09-25 23:33:12,853][_logging.py:64 -                error() ] error from callback <function _WebSocketManager._connect.<locals>.<lambda> at 0x7f63055fea70>: Authorization for Unified V5 (Auth) failed. Please check your API keys and restart. Raw error: {'success': False, 'ret_msg': 'Params Error', 'op': 'auth', 'conn_id': 'ck4hhhddaugqefbq5isg-2a5e'}
[2023-09-25 23:33:13,077][_logging.py:64 -                error() ] error from callback <function _WebSocketManager._connect.<locals>.<lambda> at 0x7f63055feb90>: Authorization for Unified V5 (Auth) failed. Please check your API keys and restart. Raw error: {'success': False, 'ret_msg': 'Params Error', 'op': 'auth', 'conn_id': 'ck4hhhddaugqefbq5isg-2a5e'}
[2023-09-25 23:33:33,147][_logging.py:64 -                error() ] error from callback <function _WebSocketManager._connect.<locals>.<lambda> at 0x7f97ef1eeb00>: Authorization for Unified V5 (Auth) failed. Please check your API keys and restart. Raw error: {'success': False, 'ret_msg': 'Params Error', 'op': 'auth', 'conn_id': 'ck4hh5hqo29qn0moor60-2a98'}
[2023-09-25 23:33:33,388][_logging.py:64 -                error() ] error from callback <function _WebSocketManager._connect.<locals>.<lambda> at 0x7f97ef1eec20>: Authorization for Unified V5 (Auth) failed. Please check your API keys and restart. Raw error: {'success': False, 'ret_msg': 'Params Error', 'op': 'auth', 'conn_id': 'ck4hh5hqo29qn0moor60-2a98'}
[2023-09-25 23:33:46,381][_logging.py:64 -                error() ] error from callback <function _WebSocketManager._connect.<locals>.<lambda> at 0x7ff794fd2b00>: Authorization for Unified V5 (Auth) failed. Please check your API keys and restart. Raw error: {'success': False, 'ret_msg': 'Params Error', 'op': 'auth', 'conn_id': 'ck4hh5hqo29qn0moor60-2a9d'}
[2023-09-25 23:33:46,614][_logging.py:64 -                error() ] error from callback <function _WebSocketManager._connect.<locals>.<lambda> at 0x7ff794fd2c20>: Authorization for Unified V5 (Auth) failed. Please check your API keys and restart. Raw error: {'success': False, 'ret_msg': 'Params Error', 'op': 'auth', 'conn_id': 'ck4hh5hqo29qn0moor60-2a9d'}
[2023-09-25 23:52:17,561][_logging.py:64 -                error() ] error from callback <function _WebSocketManager._connect.<locals>.<lambda> at 0x7fd86f3d2a70>: Authorization for Unified V5 (Auth) failed. Please check your API keys and restart. Raw error: {'success': False, 'ret_msg': 'Params Error', 'op': 'auth', 'conn_id': 'ck4hhhddaugqefbq5isg-2aen'}
[2023-09-25 23:52:17,798][_logging.py:64 -                error() ] error from callback <function _WebSocketManager._connect.<locals>.<lambda> at 0x7fd86f3d2b90>: Authorization for Unified V5 (Auth) failed. Please check your API keys and restart. Raw error: {'success': False, 'ret_msg': 'Params Error', 'op': 'auth', 'conn_id': 'ck4hhhddaugqefbq5isg-2aen'}
